<?xml version="1.0"?>

<robot name="self_balance">

    <material name='green'>
        <color rgba="0.0 0.5 0.0 1.0"/>
    </material>

    <link name="base_foot"></link>

    <link name="base_link">
        <visual>
            <geometry>
                <box size="0.03 0.07 0.15"/>
            </geometry>
            <origin xyz="0.0 0.0 0.075" rpy="0.0 0.0 0.0"/>
        </visual>
    </link>

    <joint name="base_foot" type="fixed">
        <origin xyz="0.0 0.0 0.015" rpy="0.0 0.0 0.0"/>
        <parent link="base_foot"/>
        <child link="base_link"/>
    </joint>

    <link name="right_wheel">
        <visual>
            <geometry>
                <cylinder radius="0.03" length="0.025"/>
            </geometry>
            <origin xyz="0.0 0.0 0.0" rpy="0.0 0.0 0.0"/>
            <material name="green"/>
        </visual>
    </link>
    
    <joint name="base_right_joint" type="continuous">
        <origin xyz="0.0 -0.0475 0.015" rpy="1.57 0.0 0.0"/>
        <parent link="base_link"/>
        <child link="right_wheel"/>
        <axis xyz="0.0 0.0 1"/>
    </joint>


    <link name="left_wheel">
        <visual>
            <geometry>
                <cylinder radius="0.03" length="0.025"/>
            </geometry>
            <origin xyz="0.0 0.0 0.0" rpy="0.0 0.0 0.0"/>
            <material name="green"/>
        </visual>
    </link>

    <joint name="base_left_joint" type="continuous">
        <origin xyz="0.0 0.0475 0.015" rpy="1.57 0.0 0.0"/>
        <parent link="base_link"/>
        <child link="left_wheel"/>
        <axis xyz="0.0 0.0 1"/>
    </joint>

</robot>